<?xml version="1.0" encoding="utf-8"?>
<!-- This URDF was automatically created by SolidWorks to URDF Exporter! Originally created by Stephen Brawner (brawner@gmail.com) 
     Commit Version: 1.6.0-4-g7f85cfe  Build Version: 1.6.7995.38578
     For more information, please see http://wiki.ros.org/sw_urdf_exporter -->
<robot
  name="lb_description">
  <link
    name="base_link">
    <inertial>
      <origin
        xyz="-0.13003 0.0065063 0.052046"
        rpy="0 0 0" />
      <mass
        value="2.5789" />
      <inertia
        ixx="0.0062135"
        ixy="-6.1303E-06"
        ixz="6.2726E-06"
        iyy="0.015216"
        iyz="-5.2473E-05"
        izz="0.012023" />
    </inertial>
    <visual>
      <origin
        xyz="0 0 0"
        rpy="0 0 0" />
      <geometry>
        <mesh
          filename="package://lb_description/meshes/base_link.STL" />
      </geometry>
      <material
        name="">
        <color
          rgba="0.75294 0.75294 0.75294 1" />
      </material>
    </visual>
    <collision>
      <origin
        xyz="0 0 0"
        rpy="0 0 0" />
      <geometry>
        <mesh
          filename="package://lb_description/meshes/base_link.STL" />
      </geometry>
    </collision>
  </link>
  <link
    name="GPS_Link">
    <inertial>
      <origin
        xyz="-2.7756E-17 0.031305 2.7756E-17"
        rpy="0 0 0" />
      <mass
        value="0.058059" />
      <inertia
        ixx="1.4148E-05"
        ixy="-6.9547E-20"
        ixz="2.0494E-21"
        iyy="2.1182E-05"
        iyz="1.7683E-20"
        izz="1.4148E-05" />
    </inertial>
    <visual>
      <origin
        xyz="0 0 0"
        rpy="0 0 0" />
      <geometry>
        <mesh
          filename="package://lb_description/meshes/GPS_Link.STL" />
      </geometry>
      <material
        name="">
        <color
          rgba="0.25098 0.25098 0.25098 1" />
      </material>
    </visual>
    <collision>
      <origin
        xyz="0 0 0"
        rpy="0 0 0" />
      <geometry>
        <mesh
          filename="package://lb_description/meshes/GPS_Link.STL" />
      </geometry>
    </collision>
  </link>
  <joint
    name="GPS_joint"
    type="continuous">
    <origin
      xyz="-0.12985 -0.14259 0.099275"
      rpy="1.5708 0 0" />
    <parent
      link="base_link" />
    <child
      link="GPS_Link" />
    <axis
      xyz="0 1 0" />
  </joint>
  <link
    name="wheel1_link">
    <inertial>
      <origin
        xyz="0 6.93889390390723E-18 0.0286496076048001"
        rpy="0 0 0" />
      <mass
        value="0.770870678114471" />
      <inertia
        ixx="0.00135326708994943"
        ixy="-5.42101086242752E-20"
        ixz="3.3547395993567E-20"
        iyy="0.00135326708994943"
        iyz="9.8255957384623E-21"
        izz="0.00210367327370543" />
    </inertial>
    <visual>
      <origin
        xyz="0 0 0"
        rpy="0 0 0" />
      <geometry>
        <mesh
          filename="package://lb_description/meshes/wheel1_link.STL" />
      </geometry>
      <material
        name="">
        <color
          rgba="0.501960784313725 0.501960784313725 0.501960784313725 1" />
      </material>
    </visual>
    <collision>
      <origin
        xyz="0 0 0"
        rpy="0 0 0" />
      <geometry>
        <mesh
          filename="package://lb_description/meshes/wheel1_link.STL" />
      </geometry>
    </collision>
  </link>
  <joint
    name="wheel1_joint"
    type="fixed">
    <origin
      xyz="0 0.06218 -0.055655"
      rpy="1.5708 0.66623 1.5708" />
    <parent
      link="base_link" />
    <child
      link="wheel1_link" />
    <axis
      xyz="1 0 0" />
  </joint>
  <link
    name="wheel2_link">
    <inertial>
      <origin
        xyz="0 0 0.0286496076048001"
        rpy="0 0 0" />
      <mass
        value="0.770870678114471" />
      <inertia
        ixx="0.00135326708994943"
        ixy="-8.13151629364128E-20"
        ixz="-1.12161304623174E-20"
        iyy="0.00135326708994943"
        iyz="2.4528901533775E-20"
        izz="0.00210367327370543" />
    </inertial>
    <visual>
      <origin
        xyz="0 0 0"
        rpy="0 0 0" />
      <geometry>
        <mesh
          filename="package://lb_description/meshes/wheel2_link.STL" />
      </geometry>
      <material
        name="">
        <color
          rgba="0.501960784313725 0.501960784313725 0.501960784313725 1" />
      </material>
    </visual>
    <collision>
      <origin
        xyz="0 0 0"
        rpy="0 0 0" />
      <geometry>
        <mesh
          filename="package://lb_description/meshes/wheel2_link.STL" />
      </geometry>
    </collision>
  </link>
  <joint
    name="wheel2_joint"
    type="continuous">
    <origin
      xyz="0 -0.17282 -0.055655"
      rpy="-1.5708 0.37374 -1.5708" />
    <parent
      link="base_link" />
    <child
      link="wheel2_link" />
    <axis
      xyz="1 0 0" />
  </joint>
  <link
    name="wheel3_link">
    <inertial>
      <origin
        xyz="0 -2.08166817117217E-17 0.035"
        rpy="0 0 0" />
      <mass
        value="0.770870678114471" />
      <inertia
        ixx="0.00135326708994943"
        ixy="2.71050543121376E-20"
        ixz="4.54642764366031E-20"
        iyy="0.00135326708994943"
        iyz="-7.90648337710223E-20"
        izz="0.00210367327370543" />
    </inertial>
    <visual>
      <origin
        xyz="0 0 0"
        rpy="0 0 0" />
      <geometry>
        <mesh
          filename="package://lb_description/meshes/wheel3_link.STL" />
      </geometry>
      <material
        name="">
        <color
          rgba="0.501960784313725 0.501960784313725 0.501960784313725 1" />
      </material>
    </visual>
    <collision>
      <origin
        xyz="0 0 0"
        rpy="0 0 0" />
      <geometry>
        <mesh
          filename="package://lb_description/meshes/wheel3_link.STL" />
      </geometry>
    </collision>
  </link>
  <joint
    name="wheel3_joint"
    type="continuous">
    <origin
      xyz="-0.25335 -0.17282 -0.055655"
      rpy="1.5708 0.3938 -1.5708" />
    <parent
      link="base_link" />
    <child
      link="wheel3_link" />
    <axis
      xyz="1 0 0" />
  </joint>
  <link
    name="wheel4_link">
    <inertial>
      <origin
        xyz="0 6.93889390390723E-18 -0.035"
        rpy="0 0 0" />
      <mass
        value="0.770870678114471" />
      <inertia
        ixx="0.00135326708994943"
        ixy="-5.42101086242752E-20"
        ixz="3.84534358175908E-20"
        iyy="0.00135326708994943"
        iyz="-3.9875052074779E-21"
        izz="0.00210367327370543" />
    </inertial>
    <visual>
      <origin
        xyz="0 0 0"
        rpy="0 0 0" />
      <geometry>
        <mesh
          filename="package://lb_description/meshes/wheel4_link.STL" />
      </geometry>
      <material
        name="">
        <color
          rgba="0.501960784313725 0.501960784313725 0.501960784313725 1" />
      </material>
    </visual>
    <collision>
      <origin
        xyz="0 0 0"
        rpy="0 0 0" />
      <geometry>
        <mesh
          filename="package://lb_description/meshes/wheel4_link.STL" />
      </geometry>
    </collision>
  </link>
  <joint
    name="wheel4_joint"
    type="continuous">
    <origin
      xyz="-0.25335 0.06218 -0.055655"
      rpy="1.5708 0.66623 1.5708" />
    <parent
      link="base_link" />
    <child
      link="wheel4_link" />
    <axis
      xyz="1 0 0" />
  </joint>
</robot>